[2024-07-20T17:47:12.774+0000] {local_task_job_runner.py:120} INFO - ::group::Pre task execution logs
[2024-07-20T17:47:12.850+0000] {taskinstance.py:2076} INFO - Dependencies all met for dep_context=non-requeueable deps ti=<TaskInstance: welcome_dag.print_random_quote scheduled__2024-07-20T17:44:00+00:00 [queued]>
[2024-07-20T17:47:12.886+0000] {taskinstance.py:2076} INFO - Dependencies all met for dep_context=requeueable deps ti=<TaskInstance: welcome_dag.print_random_quote scheduled__2024-07-20T17:44:00+00:00 [queued]>
[2024-07-20T17:47:12.887+0000] {taskinstance.py:2306} INFO - Starting attempt 1 of 1
[2024-07-20T17:47:12.980+0000] {taskinstance.py:2330} INFO - Executing <Task(PythonOperator): print_random_quote> on 2024-07-20 17:44:00+00:00
[2024-07-20T17:47:12.997+0000] {standard_task_runner.py:64} INFO - Started process 382 to run task
[2024-07-20T17:47:13.001+0000] {standard_task_runner.py:90} INFO - Running: ['airflow', 'tasks', 'run', 'welcome_dag', 'print_random_quote', 'scheduled__2024-07-20T17:44:00+00:00', '--job-id', '32', '--raw', '--subdir', 'DAGS_FOLDER/welcome_dag.py', '--cfg-path', '/tmp/tmpbnyqlidx']
[2024-07-20T17:47:13.004+0000] {standard_task_runner.py:91} INFO - Job 32: Subtask print_random_quote
[2024-07-20T17:47:13.194+0000] {task_command.py:426} INFO - Running <TaskInstance: welcome_dag.print_random_quote scheduled__2024-07-20T17:44:00+00:00 [running]> on host 4bcd39c96955
[2024-07-20T17:47:13.671+0000] {taskinstance.py:2648} INFO - Exporting env vars: AIRFLOW_CTX_DAG_OWNER='airflow' AIRFLOW_CTX_DAG_ID='welcome_dag' AIRFLOW_CTX_TASK_ID='print_random_quote' AIRFLOW_CTX_EXECUTION_DATE='2024-07-20T17:44:00+00:00' AIRFLOW_CTX_TRY_NUMBER='1' AIRFLOW_CTX_DAG_RUN_ID='scheduled__2024-07-20T17:44:00+00:00'
[2024-07-20T17:47:13.672+0000] {taskinstance.py:430} INFO - ::endgroup::
[2024-07-20T17:47:17.720+0000] {taskinstance.py:441} INFO - ::group::Post task execution logs
[2024-07-20T17:47:17.723+0000] {taskinstance.py:2905} ERROR - Task failed with exception
Traceback (most recent call last):
  File "/home/airflow/.local/lib/python3.12/site-packages/urllib3/connection.py", line 203, in _new_conn
    sock = connection.create_connection(
           ^^^^^^^^^^^^^^^^^^^^^^^^^^^^^
  File "/home/airflow/.local/lib/python3.12/site-packages/urllib3/util/connection.py", line 60, in create_connection
    for res in socket.getaddrinfo(host, port, family, socket.SOCK_STREAM):
               ^^^^^^^^^^^^^^^^^^^^^^^^^^^^^^^^^^^^^^^^^^^^^^^^^^^^^^^^^^
  File "/usr/local/lib/python3.12/socket.py", line 964, in getaddrinfo
    for res in _socket.getaddrinfo(host, port, family, type, proto, flags):
               ^^^^^^^^^^^^^^^^^^^^^^^^^^^^^^^^^^^^^^^^^^^^^^^^^^^^^^^^^^^
socket.gaierror: [Errno -2] Name or service not known

The above exception was the direct cause of the following exception:

Traceback (most recent call last):
  File "/home/airflow/.local/lib/python3.12/site-packages/urllib3/connectionpool.py", line 791, in urlopen
    response = self._make_request(
               ^^^^^^^^^^^^^^^^^^^
  File "/home/airflow/.local/lib/python3.12/site-packages/urllib3/connectionpool.py", line 492, in _make_request
    raise new_e
  File "/home/airflow/.local/lib/python3.12/site-packages/urllib3/connectionpool.py", line 468, in _make_request
    self._validate_conn(conn)
  File "/home/airflow/.local/lib/python3.12/site-packages/urllib3/connectionpool.py", line 1097, in _validate_conn
    conn.connect()
  File "/home/airflow/.local/lib/python3.12/site-packages/urllib3/connection.py", line 611, in connect
    self.sock = sock = self._new_conn()
                       ^^^^^^^^^^^^^^^^
  File "/home/airflow/.local/lib/python3.12/site-packages/urllib3/connection.py", line 210, in _new_conn
    raise NameResolutionError(self.host, self, e) from e
urllib3.exceptions.NameResolutionError: <urllib3.connection.HTTPSConnection object at 0x7f071e568fe0>: Failed to resolve 'api.quotable.io' ([Errno -2] Name or service not known)

The above exception was the direct cause of the following exception:

Traceback (most recent call last):
  File "/home/airflow/.local/lib/python3.12/site-packages/requests/adapters.py", line 667, in send
    resp = conn.urlopen(
           ^^^^^^^^^^^^^
  File "/home/airflow/.local/lib/python3.12/site-packages/urllib3/connectionpool.py", line 845, in urlopen
    retries = retries.increment(
              ^^^^^^^^^^^^^^^^^^
  File "/home/airflow/.local/lib/python3.12/site-packages/urllib3/util/retry.py", line 515, in increment
    raise MaxRetryError(_pool, url, reason) from reason  # type: ignore[arg-type]
    ^^^^^^^^^^^^^^^^^^^^^^^^^^^^^^^^^^^^^^^^^^^^^^^^^^^
urllib3.exceptions.MaxRetryError: HTTPSConnectionPool(host='api.quotable.io', port=443): Max retries exceeded with url: /random (Caused by NameResolutionError("<urllib3.connection.HTTPSConnection object at 0x7f071e568fe0>: Failed to resolve 'api.quotable.io' ([Errno -2] Name or service not known)"))

During handling of the above exception, another exception occurred:

Traceback (most recent call last):
  File "/home/airflow/.local/lib/python3.12/site-packages/airflow/models/taskinstance.py", line 465, in _execute_task
    result = _execute_callable(context=context, **execute_callable_kwargs)
             ^^^^^^^^^^^^^^^^^^^^^^^^^^^^^^^^^^^^^^^^^^^^^^^^^^^^^^^^^^^^^
  File "/home/airflow/.local/lib/python3.12/site-packages/airflow/models/taskinstance.py", line 432, in _execute_callable
    return execute_callable(context=context, **execute_callable_kwargs)
           ^^^^^^^^^^^^^^^^^^^^^^^^^^^^^^^^^^^^^^^^^^^^^^^^^^^^^^^^^^^^
  File "/home/airflow/.local/lib/python3.12/site-packages/airflow/models/baseoperator.py", line 401, in wrapper
    return func(self, *args, **kwargs)
           ^^^^^^^^^^^^^^^^^^^^^^^^^^^
  File "/home/airflow/.local/lib/python3.12/site-packages/airflow/operators/python.py", line 235, in execute
    return_value = self.execute_callable()
                   ^^^^^^^^^^^^^^^^^^^^^^^
  File "/home/airflow/.local/lib/python3.12/site-packages/airflow/operators/python.py", line 252, in execute_callable
    return self.python_callable(*self.op_args, **self.op_kwargs)
           ^^^^^^^^^^^^^^^^^^^^^^^^^^^^^^^^^^^^^^^^^^^^^^^^^^^^^
  File "/opt/airflow/dags/welcome_dag.py", line 27, in print_random_quote
    response = requests.get('https://api.quotable.io/random')
               ^^^^^^^^^^^^^^^^^^^^^^^^^^^^^^^^^^^^^^^^^^^^^^
  File "/home/airflow/.local/lib/python3.12/site-packages/requests/api.py", line 73, in get
    return request("get", url, params=params, **kwargs)
           ^^^^^^^^^^^^^^^^^^^^^^^^^^^^^^^^^^^^^^^^^^^^
  File "/home/airflow/.local/lib/python3.12/site-packages/requests/api.py", line 59, in request
    return session.request(method=method, url=url, **kwargs)
           ^^^^^^^^^^^^^^^^^^^^^^^^^^^^^^^^^^^^^^^^^^^^^^^^^
  File "/home/airflow/.local/lib/python3.12/site-packages/requests/sessions.py", line 589, in request
    resp = self.send(prep, **send_kwargs)
           ^^^^^^^^^^^^^^^^^^^^^^^^^^^^^^
  File "/home/airflow/.local/lib/python3.12/site-packages/requests/sessions.py", line 703, in send
    r = adapter.send(request, **kwargs)
        ^^^^^^^^^^^^^^^^^^^^^^^^^^^^^^^
  File "/home/airflow/.local/lib/python3.12/site-packages/requests/adapters.py", line 700, in send
    raise ConnectionError(e, request=request)
requests.exceptions.ConnectionError: HTTPSConnectionPool(host='api.quotable.io', port=443): Max retries exceeded with url: /random (Caused by NameResolutionError("<urllib3.connection.HTTPSConnection object at 0x7f071e568fe0>: Failed to resolve 'api.quotable.io' ([Errno -2] Name or service not known)"))
[2024-07-20T17:47:17.772+0000] {taskinstance.py:1206} INFO - Marking task as FAILED. dag_id=welcome_dag, task_id=print_random_quote, run_id=scheduled__2024-07-20T17:44:00+00:00, execution_date=20240720T174400, start_date=20240720T174712, end_date=20240720T174717
[2024-07-20T17:47:17.835+0000] {standard_task_runner.py:110} ERROR - Failed to execute job 32 for task print_random_quote (HTTPSConnectionPool(host='api.quotable.io', port=443): Max retries exceeded with url: /random (Caused by NameResolutionError("<urllib3.connection.HTTPSConnection object at 0x7f071e568fe0>: Failed to resolve 'api.quotable.io' ([Errno -2] Name or service not known)")); 382)
[2024-07-20T17:47:17.859+0000] {local_task_job_runner.py:243} INFO - Task exited with return code 1
[2024-07-20T17:47:17.895+0000] {taskinstance.py:3503} INFO - 0 downstream tasks scheduled from follow-on schedule check
[2024-07-20T17:47:17.898+0000] {local_task_job_runner.py:222} INFO - ::endgroup::
